/*
 * TestBadAllocExceptionDemo.cpp
 *
 *  Created on: Dec 30, 2021
 *      Author: mao
 */


#include <iostream>
using namespace std;

int testBadAllocExceptionDemo()
{
	try
	{
		for (int i = 1; i <= 100; i++)
		{
			new int[70000000];
			cout << i << " arrays have been created" << endl;
		}
	}
	catch (bad_alloc& ex)
	{
		cout << "Exception: " << ex.what() << endl;
	}

	return 0;
}

